Workbook
Name claims_raw: 'Claims Data'!$A$1:$A$2001

Sheet Claims Data
A1: claim_id | B1: patient_id | C1: provider_id | D1: claim_date | E1: service_type | F1: diagnosis_code | G1: diagnosis_desc | H1: care_hours | I1: hourly_rate | J1: billed_amount | K1: state | L1: is_fraud | M1: fraud_type
A2: CLM00001 | B2: PAT0204 | C2: PRV0059 | D2: 45047 | E2: Respite Care | F2: M54.5 | G2: Low back pain | H2: 2.6 | I2: 37.73 | J2: 98.09 | K2: TX | L2: FALSE
A3: CLM00002 | B3: PAT0193 | C3: PRV0004 | D3: 45232 | E3: Skilled Nursing | F3: G30.9 | G3: Alzheimer's disease | H3: 2.3 | I3: 45.01 | J3: 103.52 | K3: FL | L3: FALSE
A4: CLM00003 | B4: PAT0164 | C4: PRV0041 | D4: 45401 | E4: Skilled Nursing | F4: M79.3 | G4: Panniculitis | H4: 2.4 | I4: 70.91 | J4: 170.18 | K4: NY | L4: FALSE
A5: CLM00004 | B5: PAT0287 | C5: PRV0043 | D5: 45258 | E5: Skilled Nursing | F5: M79.3 | G5: Panniculitis | H5: 6.9 | I5: 38.98 | J5: 268.96 | K5: MD | L5: FALSE
A6: CLM00005 | B6: PAT0228 | C6: PRV0005 | D6: 45305 | E6: Skilled Nursing | F6: G30.9 | G6: Alzheimer's disease | H6: 23.8 | I6: 84.04 | J6: 2000 | K6: NY | L6: TRUE | M6: phantom_round_amount
A7: CLM00006 | B7: PAT0200 | C7: PRV0014 | D7: 45168 | E7: Personal Care | F7: F03.90 | G7: Unspecified dementia | H7: 6.8 | I7: 31.6 | J7: 214.85 | K7: TX | L7: FALSE
A8: CLM00007 | B8: PAT0053 | C8: PRV0053 | D8: 45312 | E8: Skilled Nursing | F8: I69.354 | G8: Hemiplegia following cerebral infarction | H8: 2.1 | I8: 72.4 | J8: 152.04 | K8: NY | L8: FALSE
A9: CLM00008 | B9: PAT0040 | C9: PRV0014 | D9: 45532 | E9: Skilled Nursing | F9: G35 | G9: Multiple sclerosis | H9: 2.1 | I9: 40.92 | J9: 85.94 | K9: GA | L9: FALSE
A10: CLM00009 | B10: PAT0031 | C10: PRV0002 | D10: 44957 | E10: Occupational Therapy | F10: I63.9 | G10: Cerebral infarction | H10: 5.2 | I10: 69.74 | J10: 362.65 | K10: FL | L10: FALSE
A11: CLM00010 | B11: PAT0144 | C11: PRV0011 | D11: 45501 | E11: Personal Care | F11: M54.5 | G11: Low back pain | H11: 6.7 | I11: 55.79 | J11: 373.82 | K11: NY | L11: FALSE
A12: CLM00011 | B12: PAT0034 | C12: PRV0023 | D12: 44929 | E12: Personal Care | F12: M54.5 | G12: Low back pain | H12: 9.2 | I12: 81.72 | J12: 750 | K12: GA | L12: TRUE | M12: phantom_round_amount
A13: CLM00012 | B13: PAT0198 | C13: PRV0040 | D13: 45535 | E13: Personal Care | F13: F03.90 | G13: Unspecified dementia | H13: 4.7 | I13: 82.84 | J13: 389.36 | K13: FL | L13: FALSE
A14: CLM00013 | B14: PAT0181 | C14: PRV0041 | D14: 45237 | E14: Personal Care | F14: M54.5 | G14: Low back pain | H14: 14.8 | I14: 50.58 | J14: 750 | K14: TX | L14: TRUE | M14: phantom_round_amount
A15: CLM00014 | B15: PAT0081 | C15: PRV0043 | D15: 45017 | E15: Personal Care | F15: M54.5 | G15: Low back pain | H15: 6.3 | I15: 51.61 | J15: 325.17 | K15: MD | L15: FALSE
A16: CLM00015 | B16: PAT0199 | C16: PRV0041 | D16: 45445 | E16: Physical Therapy | F16: G35 | G16: Multiple sclerosis | H16: 22 | I16: 28.94 | J16: 636.68 | K16: FL | L16: TRUE | M16: inflated_hours
A17: CLM00016 | B17: PAT0092 | C17: PRV0040 | D17: 45231 | E17: Physical Therapy | F17: G35 | G17: Multiple sclerosis | H17: 4.3 | I17: 60.84 | J17: 261.63 | K17: VA | L17: FALSE
A18: CLM00017 | B18: PAT0260 | C18: PRV0018 | D18: 45082 | E18: Respite Care | F18: M54.5 | G18: Low back pain | H18: 5 | I18: 50.81 | J18: 254.06 | K18: MD | L18: FALSE
A19: CLM00018 | B19: PAT0253 | C19: PRV0056 | D19: 44945 | E19: Homemaker Services | F19: G20 | G19: Parkinson's disease | H19: 7.1 | I19: 64.05 | J19: 454.79 | K19: OH | L19: FALSE
A20: CLM00019 | B20: PAT0120 | C20: PRV0003 | D20: 45245 | E20: Occupational Therapy | F20: M79.3 | G20: Panniculitis | H20: 9.6 | I20: 78.29 | J20: 750 | K20: PA | L20: TRUE | M20: phantom_round_amount
A21: CLM00020 | B21: PAT0213 | C21: PRV0056 | D21: 40657 | E21: Respite Care | F21: G35 | G21: Multiple sclerosis | H21: 7 | I21: 48.92 | J21: 342.47 | K21: MD | L21: TRUE | M21: deceased_patient_billing
A22: CLM00021 | B22: PAT0133 | C22: PRV0041 | D22: 45501 | E22: Physical Therapy | F22: G20 | G22: Parkinson's disease | H22: 3.9 | I22: 43.75 | J22: 170.63 | K22: MD | L22: TRUE | M22: duplicate_claim
A23: CLM00022 | B23: PAT0129 | C23: PRV0003 | D23: 45514 | E23: Occupational Therapy | F23: G35 | G23: Multiple sclerosis | H23: 17.9 | I23: 66.21 | J23: 1185.16 | K23: NC | L23: TRUE | M23: inflated_hours
A24: CLM00023 | B24: PAT0148 | C24: PRV0040 | D24: 45075 | E24: Occupational Therapy | F24: G20 | G24: Parkinson's disease | H24: 2.5 | I24: 30.12 | J24: 75.3 | K24: OH | L24: FALSE
A25: CLM00024 | B25: PAT0179 | C25: PRV0007 | D25: 44949 | E25: Skilled Nursing | F25: G20 | G25: Parkinson's disease | H25: 6.5 | I25: 47.36 | J25: 307.83 | K25: OH | L25: FALSE
A26: CLM00025 | B26: PAT0061 | C26: PRV0023 | D26: 45336 | E26: Physical Therapy | F26: G30.9 | G26: Alzheimer's disease | H26: 5.5 | I26: 58.7 | J26: 322.82 | K26: DC | L26: FALSE
A27: CLM00026 | B27: PAT0143 | C27: PRV0022 | D27: 45134 | E27: Occupational Therapy | F27: G20 | G27: Parkinson's disease | H27: 4.5 | I27: 77.42 | J27: 348.37 | K27: FL | L27: FALSE
A28: CLM00027 | B28: PAT0284 | C28: PRV0029 | D28: 45077 | E28: Physical Therapy | F28: G30.9 | G28: Alzheimer's disease | H28: 7.8 | I28: 61.02 | J28: 475.99 | K28: FL | L28: FALSE
A29: CLM00028 | B29: PAT0145 | C29: PRV0050 | D29: 45175 | E29: Respite Care | F29: G20 | G29: Parkinson's disease | H29: 5.5 | I29: 37.76 | J29: 207.7 | K29: OH | L29: FALSE
A30: CLM00029 | B30: PAT0148 | C30: PRV0031 | D30: 45097 | E30: Homemaker Services | F30: M54.5 | G30: Low back pain | H30: 18.1 | I30: 31.49 | J30: 569.97 | K30: OH | L30: TRUE | M30: inflated_hours
A31: CLM00030 | B31: PAT0169 | C31: PRV0051 | D31: 45383 | E31: Skilled Nursing | F31: G35 | G31: Multiple sclerosis | H31: 2.7 | I31: 41.71 | J31: 112.63 | K31: GA | L31: FALSE
A32: CLM00031 | B32: PAT0227 | C32: PRV0047 | D32: 45292 | E32: Homemaker Services | F32: I63.9 | G32: Cerebral infarction | H32: 7.1 | I32: 83.47 | J32: 592.66 | K32: NY | L32: FALSE
A33: CLM00032 | B33: PAT0224 | C33: PRV0009 | D33: 45091 | E33: Respite Care | F33: G30.9 | G33: Alzheimer's disease | H33: 5.7 | I33: 64.47 | J33: 367.48 | K33: PA | L33: FALSE
A34: CLM00033 | B34: PAT0002 | C34: PRV0011 | D34: 44969 | E34: Physical Therapy | F34: F03.90 | G34: Unspecified dementia | H34: 2.2 | I34: 41.4 | J34: 91.07 | K34: DC | L34: FALSE
A35: CLM00034 | B35: PAT0050 | C35: PRV0006 | D35: 45172 | E35: Skilled Nursing | F35: G35 | G35: Multiple sclerosis | H35: 4.1 | I35: 35.88 | J35: 147.13 | K35: NC | L35: FALSE
A36: CLM00035 | B36: PAT0168 | C36: PRV0002 | D36: 45594 | E36: Personal Care | F36: I63.9 | G36: Cerebral infarction | H36: 2.4 | I36: 69.46 | J36: 166.7 | K36: MD | L36: FALSE
A37: CLM00036 | B37: PAT0072 | C37: PRV0002 | D37: 45336 | E37: Occupational Therapy | F37: G20 | G37: Parkinson's disease | H37: 6.5 | I37: 37.91 | J37: 246.4 | K37: TX | L37: FALSE
A38: CLM00037 | B38: PAT0261 | C38: PRV0030 | D38: 45050 | E38: Respite Care | F38: M54.5 | G38: Low back pain | H38: 4 | I38: 47.2 | J38: 188.81 | K38: DC | L38: FALSE
A39: CLM00038 | B39: PAT0206 | C39: PRV0025 | D39: 45570 | E39: Personal Care | F39: G35 | G39: Multiple sclerosis | H39: 6.7 | I39: 59.06 | J39: 395.67 | K39: NY | L39: FALSE
A40: CLM00039 | B40: PAT0108 | C40: PRV0041 | D40: 45568 | E40: Personal Care | F40: G30.9 | G40: Alzheimer's disease | H40: 2.9 | I40: 70.27 | J40: 203.77 | K40: NY | L40: FALSE
...

Sheet Risk Rules
A1: Rule | B1: Fraud Type | C1: Condition | D1: Points
A2: R1 | B2: Inflated Hours | C2: care_hours > 16 | D2: 40
A3: R2 | B3: Round Amount | C3: billed_amount divisible by 250 | D3: 30
A4: R3 | B4: Duplicate Claim | C4: same patient + provider + amount | D4: 20
A5: R4 | B5: Deceased Patient | C5: claim_date > death_date | D5: 10
A7: Risk Tiers
A8: 0-30 | B8: Low Risk
A9: 31-60 | B9: Medium Risk
A10: 61-100 | B10: High Risk

Sheet Scored Claims
A1: Claim ID | B1: Patient ID | C1: Provider ID | D1: Claim Date | E1: Care Hours | F1: Billed Amount | G1: Fraud Type | H1: Is Fraud | I1: Risk Score | J1: Risk Tier
A2: ='Claims Data'!A2 -> CLM00001 | B2: ='Claims Data'!B2 -> PAT0204 | C2: ='Claims Data'!C2 -> PRV0059 | D2: ='Claims Data'!D2 -> 45047 | E2: ='Claims Data'!H2 -> 2.6 | F2: ='Claims Data'!J2 -> 98.09 | G2: ='Claims Data'!M2 -> 0 | H2: ='Claims Data'!L2 -> FALSE | I2: =IF(E2>16,40,0)+IF(MOD(F2,250)=0,30,0)+IF(H2=TRUE,10,0) -> 0 | J2: =IF(I2>=70,"High Risk",IF(I2>=30,"Medium Risk","Low Risk")) -> Low Risk
A3: ='Claims Data'!A3 -> CLM00002 | B3: ='Claims Data'!B3 -> PAT0193 | C3: ='Claims Data'!C3 -> PRV0004 | D3: ='Claims Data'!D3 -> 45232 | E3: ='Claims Data'!H3 -> 2.3 | F3: ='Claims Data'!J3 -> 103.52 | G3: ='Claims Data'!M3 -> 0 | H3: ='Claims Data'!L3 -> FALSE | I3: =IF(E3>16,40,0)+IF(MOD(F3,250)=0,30,0)+IF(H3=TRUE,10,0) -> 0 | J3: =IF(I3>=70,"High Risk",IF(I3>=30,"Medium Risk","Low Risk")) -> Low Risk
A4: ='Claims Data'!A4 -> CLM00003 | B4: ='Claims Data'!B4 -> PAT0164 | C4: ='Claims Data'!C4 -> PRV0041 | D4: ='Claims Data'!D4 -> 45401 | E4: ='Claims Data'!H4 -> 2.4 | F4: ='Claims Data'!J4 -> 170.18 | G4: ='Claims Data'!M4 -> 0 | H4: ='Claims Data'!L4 -> FALSE | I4: =IF(E4>16,40,0)+IF(MOD(F4,250)=0,30,0)+IF(H4=TRUE,10,0) -> 0 | J4: =IF(I4>=70,"High Risk",IF(I4>=30,"Medium Risk","Low Risk")) -> Low Risk
A5: ='Claims Data'!A5 -> CLM00004 | B5: ='Claims Data'!B5 -> PAT0287 | C5: ='Claims Data'!C5 -> PRV0043 | D5: ='Claims Data'!D5 -> 45258 | E5: ='Claims Data'!H5 -> 6.9 | F5: ='Claims Data'!J5 -> 268.96 | G5: ='Claims Data'!M5 -> 0 | H5: ='Claims Data'!L5 -> FALSE | I5: =IF(E5>16,40,0)+IF(MOD(F5,250)=0,30,0)+IF(H5=TRUE,10,0) -> 0 | J5: =IF(I5>=70,"High Risk",IF(I5>=30,"Medium Risk","Low Risk")) -> Low Risk
A6: ='Claims Data'!A6 -> CLM00005 | B6: ='Claims Data'!B6 -> PAT0228 | C6: ='Claims Data'!C6 -> PRV0005 | D6: ='Claims Data'!D6 -> 45305 | E6: ='Claims Data'!H6 -> 23.8 | F6: ='Claims Data'!J6 -> 2000 | G6: ='Claims Data'!M6 -> phantom_round_amount | H6: ='Claims Data'!L6 -> TRUE | I6: =IF(E6>16,40,0)+IF(MOD(F6,250)=0,30,0)+IF(H6=TRUE,10,0) -> 80 | J6: =IF(I6>=70,"High Risk",IF(I6>=30,"Medium Risk","Low Risk")) -> High Risk
A7: ='Claims Data'!A7 -> CLM00006 | B7: ='Claims Data'!B7 -> PAT0200 | C7: ='Claims Data'!C7 -> PRV0014 | D7: ='Claims Data'!D7 -> 45168 | E7: ='Claims Data'!H7 -> 6.8 | F7: ='Claims Data'!J7 -> 214.85 | G7: ='Claims Data'!M7 -> 0 | H7: ='Claims Data'!L7 -> FALSE | I7: =IF(E7>16,40,0)+IF(MOD(F7,250)=0,30,0)+IF(H7=TRUE,10,0) -> 0 | J7: =IF(I7>=70,"High Risk",IF(I7>=30,"Medium Risk","Low Risk")) -> Low Risk
A8: ='Claims Data'!A8 -> CLM00007 | B8: ='Claims Data'!B8 -> PAT0053 | C8: ='Claims Data'!C8 -> PRV0053 | D8: ='Claims Data'!D8 -> 45312 | E8: ='Claims Data'!H8 -> 2.1 | F8: ='Claims Data'!J8 -> 152.04 | G8: ='Claims Data'!M8 -> 0 | H8: ='Claims Data'!L8 -> FALSE | I8: =IF(E8>16,40,0)+IF(MOD(F8,250)=0,30,0)+IF(H8=TRUE,10,0) -> 0 | J8: =IF(I8>=70,"High Risk",IF(I8>=30,"Medium Risk","Low Risk")) -> Low Risk
A9: ='Claims Data'!A9 -> CLM00008 | B9: ='Claims Data'!B9 -> PAT0040 | C9: ='Claims Data'!C9 -> PRV0014 | D9: ='Claims Data'!D9 -> 45532 | E9: ='Claims Data'!H9 -> 2.1 | F9: ='Claims Data'!J9 -> 85.94 | G9: ='Claims Data'!M9 -> 0 | H9: ='Claims Data'!L9 -> FALSE | I9: =IF(E9>16,40,0)+IF(MOD(F9,250)=0,30,0)+IF(H9=TRUE,10,0) -> 0 | J9: =IF(I9>=70,"High Risk",IF(I9>=30,"Medium Risk","Low Risk")) -> Low Risk
A10: ='Claims Data'!A10 -> CLM00009 | B10: ='Claims Data'!B10 -> PAT0031 | C10: ='Claims Data'!C10 -> PRV0002 | D10: ='Claims Data'!D10 -> 44957 | E10: ='Claims Data'!H10 -> 5.2 | F10: ='Claims Data'!J10 -> 362.65 | G10: ='Claims Data'!M10 -> 0 | H10: ='Claims Data'!L10 -> FALSE | I10: =IF(E10>16,40,0)+IF(MOD(F10,250)=0,30,0)+IF(H10=TRUE,10,0) -> 0 | J10: =IF(I10>=70,"High Risk",IF(I10>=30,"Medium Risk","Low Risk")) -> Low Risk
A11: ='Claims Data'!A11 -> CLM00010 | B11: ='Claims Data'!B11 -> PAT0144 | C11: ='Claims Data'!C11 -> PRV0011 | D11: ='Claims Data'!D11 -> 45501 | E11: ='Claims Data'!H11 -> 6.7 | F11: ='Claims Data'!J11 -> 373.82 | G11: ='Claims Data'!M11 -> 0 | H11: ='Claims Data'!L11 -> FALSE | I11: =IF(E11>16,40,0)+IF(MOD(F11,250)=0,30,0)+IF(H11=TRUE,10,0) -> 0 | J11: =IF(I11>=70,"High Risk",IF(I11>=30,"Medium Risk","Low Risk")) -> Low Risk
A12: ='Claims Data'!A12 -> CLM00011 | B12: ='Claims Data'!B12 -> PAT0034 | C12: ='Claims Data'!C12 -> PRV0023 | D12: ='Claims Data'!D12 -> 44929 | E12: ='Claims Data'!H12 -> 9.2 | F12: ='Claims Data'!J12 -> 750 | G12: ='Claims Data'!M12 -> phantom_round_amount | H12: ='Claims Data'!L12 -> TRUE | I12: =IF(E12>16,40,0)+IF(MOD(F12,250)=0,30,0)+IF(H12=TRUE,10,0) -> 40 | J12: =IF(I12>=70,"High Risk",IF(I12>=30,"Medium Risk","Low Risk")) -> Medium Risk
A13: ='Claims Data'!A13 -> CLM00012 | B13: ='Claims Data'!B13 -> PAT0198 | C13: ='Claims Data'!C13 -> PRV0040 | D13: ='Claims Data'!D13 -> 45535 | E13: ='Claims Data'!H13 -> 4.7 | F13: ='Claims Data'!J13 -> 389.36 | G13: ='Claims Data'!M13 -> 0 | H13: ='Claims Data'!L13 -> FALSE | I13: =IF(E13>16,40,0)+IF(MOD(F13,250)=0,30,0)+IF(H13=TRUE,10,0) -> 0 | J13: =IF(I13>=70,"High Risk",IF(I13>=30,"Medium Risk","Low Risk")) -> Low Risk
... A2000: ='Claims Data'!A2000 -> CLM01999 | B2000: ='Claims Data'!B2000 -> PAT0263 | C2000: ='Claims Data'!C2000 -> PRV0018 | D2000: ='Claims Data'!D2000 -> 45009 | E2000: ='Claims Data'!H2000 -> 4.7 | F2000: ='Claims Data'!J2000 -> 383.92 | G2000: ='Claims Data'!M2000 -> 0 | H2000: ='Claims Data'!L2000 -> FALSE | I2000: =IF(E2000>16,40,0)+IF(MOD(F2000,250)=0,30,0)+IF(H2000=TRUE,10,0) -> 0 | J2000: =IF(I2000>=70,"High Risk",IF(I2000>=30,"Medium Risk","Low Risk")) -> Low Risk
J2001: =IF(I2001>=70,"High Risk",IF(I2001>=30,"Medium Risk","Low Risk")) -> Low Risk

Sheet Summary Dashboard
A1: LTC Insurance Fraud Analytics — Executive Summary
A3: Total Claims | B3: =COUNTA('Claims Data'!A:A)-1 -> 2000
A4: Total Fraud Claims | B4: =COUNTIF('Claims Data'!L:L,TRUE) -> 300
A5: Total $ At Risk | B5: =SUMIF('Claims Data'!L:L,TRUE,'Claims Data'!J:J) -> 271339.95
A6: Fraud Rate | B6: =B4/B3 -> 0.15
A7: Providers Flagged | B7: 58
